# Exception
- 에러 발생 시 처리
- `try` ~ `except` 사용
```python
try :
    num1 = int(input("num1: "))
    num2 = int(input("num2: "))
    print("{0} / {1} = {2|".format(num1, num2, int(num1 / num2)))
except ValueError:
    print("error")
except ZeroDivisionError as err: 
    print(err) # 내장 에러메시지 출력

```

## user-Exception
```python
class BigNumberError(Exception):
    pass

try :
    num1 = int(input("num1: "))
    num2 = int(input("num2: "))
    
    if num1 >= 10 or num2 >= 10:
        raise BigNumberError # error pop
    print("{0} / {1} = {2|".format(num1, num2, int(num1 / num2)))
except BigNumberError:
    print("error")
```

## finally 
- 예외 처리 중 예외 발생과 상관없이 무조건 실행됨
```python
class BigNumberError(Exception):
    pass

try :
    num1 = int(input("num1: "))
    num2 = int(input("num2: "))
    
    if num1 >= 10 or num2 >= 10:
        raise BigNumberError # error pop
    print("{0} / {1} = {2|".format(num1, num2, int(num1 / num2)))
except BigNumberError:
    print("error")
finally:
    print("finally")
```